<?xml version="1.0" encoding="UTF-8"?>
<!-- Generated by org.testng.reporters.JUnitReportReporter -->
<testsuite hostname="swati_pc" failures="0" tests="3" name="practice.test.InvoiceTest" time="6.441" errors="1" timestamp="2025-09-05T17:17:48 IST" skipped="0">
  <testcase classname="practice.test.InvoiceTest" name="configAfterSuite" time="3.355">
    <error message="Cannot invoke &quot;java.sql.Connection.close()&quot; because &quot;this.con&quot; is null" type="java.lang.NullPointerException">
      <![CDATA[java.lang.NullPointerException: Cannot invoke "java.sql.Connection.close()" because "this.con" is null
at com.comcast.crm.generic.databaseutility.DatabaseUtility.closeConnection(DatabaseUtility.java:24)
at com.crm.genericbaseutility.BaseClass.configAfterSuite(BaseClass.java:105)
at java.base/jdk.internal.reflect.DirectMethodHandleAccessor.invoke(DirectMethodHandleAccessor.java:103)
at java.base/java.lang.reflect.Method.invoke(Method.java:580)
at org.testng.internal.invokers.MethodInvocationHelper.invokeMethod(MethodInvocationHelper.java:141)
at org.testng.internal.invokers.MethodInvocationHelper.invokeMethodConsideringTimeout(MethodInvocationHelper.java:71)
at org.testng.internal.invokers.ConfigInvoker.invokeConfigurationMethod(ConfigInvoker.java:400)
at org.testng.internal.invokers.ConfigInvoker.invokeConfigurations(ConfigInvoker.java:333)
at org.testng.SuiteRunner.privateRun(SuiteRunner.java:386)
at org.testng.SuiteRunner.run(SuiteRunner.java:312)
at org.testng.SuiteRunnerWorker.runSuite(SuiteRunnerWorker.java:52)
at org.testng.SuiteRunnerWorker.run(SuiteRunnerWorker.java:95)
at org.testng.TestNG.runSuitesSequentially(TestNG.java:1274)
at org.testng.TestNG.runSuitesLocally(TestNG.java:1208)
at org.testng.TestNG.runSuites(TestNG.java:1112)
at org.testng.TestNG.run(TestNG.java:1079)
at org.testng.remote.AbstractRemoteTestNG.run(AbstractRemoteTestNG.java:115)
at org.testng.remote.RemoteTestNG.initAndRun(RemoteTestNG.java:293)
at org.testng.remote.RemoteTestNG.main(RemoteTestNG.java:91)
]]>
    </error>
  </testcase> <!-- configAfterSuite -->
  <testcase classname="practice.test.InvoiceTest" name="createInvoiceTest" time="3.085">
    <system-out>
      <![CDATA[Execute createInvoiceTest ]]>
    </system-out>
  </testcase> <!-- createInvoiceTest -->
  <testcase classname="practice.test.InvoiceTest" name="createInvoiceithContactTest" time="0.001">
    <system-out>
      <![CDATA[Execute createInvoiceithContactTest ]]>
    </system-out>
  </testcase> <!-- createInvoiceithContactTest -->
  <system-out>
    <![CDATA[Execute createInvoiceTest 
Execute createInvoiceithContactTest ]]>
  </system-out>
</testsuite> <!-- practice.test.InvoiceTest -->
